<?xml version="1.0" encoding="utf-8"?>
<!-- This URDF was automatically created by SolidWorks to URDF Exporter! Originally created by Stephen Brawner (brawner@gmail.com) 
     Commit Version: 1.6.0-4-g7f85cfe  Build Version: 1.6.7995.38578
     For more information, please see http://wiki.ros.org/sw_urdf_exporter -->
<robot
  name="dmgo_description">
 
    <!-- <mujoco>
	  <compiler
	  meshdir="../meshes"
	  balanceinertia="true"
	  discardvisual="false"/>
  </mujoco>

  <link name="world"/>
  <joint name="floating_base" type="floating"> 
      <origin xyz="0 0 0" rpy="0 0 0" />
      <parent link="world"/>
      <child link="base"/>
  </joint> -->
  <gazebo>
    <plugin filename="liblegged_hw_sim.so" name="gazebo_ros_control">
      <robotNamespace>/</robotNamespace>
      <robotParam>legged_robot_description</robotParam>
      <robotSimType>legged_gazebo/LeggedHWSim</robotSimType>
    </plugin>
  </gazebo>
  <gazebo>
    <plugin filename="libgazebo_ros_p3d.so" name="p3d_base_controller">
      <alwaysOn>true</alwaysOn>
      <updateRate>1000.0</updateRate>
      <bodyName>base</bodyName>
      <topicName>ground_truth/state</topicName>
      <gaussianNoise>0</gaussianNoise>
      <frameName>world</frameName>
      <xyzOffsets>0 0 0</xyzOffsets>
      <rpyOffsets>0 0 0</rpyOffsets>
    </plugin>
  </gazebo>

  <link name="base">
    <inertial>
      <origin
        xyz="-0.001955 0.002743 -0.068608"
        rpy="0 0 0" />
      <mass
        value="6.889103" />
      <inertia
        ixx="0.035976"
        ixy="0.000077"
        ixz="-0.000148"
        iyy="0.081109"
        iyz="0.000272"
        izz="0.103076" />
    </inertial>
    <visual>
      <origin
        xyz="0 0 0"
        rpy="0 0 0" />
      <geometry>
        <!-- <mesh
          filename="../meshes/base.STL" /> -->
           <mesh
          filename="package://legged_damiao_description/meshes/dmgo/base.STL" />
      </geometry>
      <material
        name="">
        <color
          rgba="0.882352941176471 0.882352941176471 0.882352941176471 1" />
      </material>
    </visual>
    <collision>
      <origin rpy="0 0 0" xyz="0 0 -0.069779"/>
      <geometry>
        <box size="0.28 0.18 0.1"/>
      </geometry>
    </collision>
  </link>

  <joint name="base_imu_joint" type="fixed">
    <origin rpy="0. 0. 0." xyz="0. 0. 0."/>
    <parent link="base"/>
    <child link="base_imu"/>
  </joint>
  <!-- Imu link -->
  <link name="base_imu">
    <inertial>
      <mass value="0.01"/>
      <origin rpy="0 0 0" xyz="0 0 0"/>
      <inertia ixx="0.000001" ixy="0" ixz="0" iyy="0.000001" iyz="0" izz="0.000001"/>
    </inertial>
    <visual>
      <origin rpy="0 0 0" xyz="0 0 0"/>
      <geometry>
        <box size="0.015 0.015 0.004"/>
      </geometry>
    </visual>
    <material name="orange">
      <color rgba="255 108 10 255"/>
    </material>
  </link>
  <gazebo reference="base_imu">
    <material>Gazebo/Orange</material>
  </gazebo>
  <gazebo reference="base_imu_joint">
    <disableFixedJointLumping>true</disableFixedJointLumping>
  </gazebo>





  <link
    name="LF_hip">
    <inertial>
      <origin
        xyz="0.047560 -0.010434 -0.000046"
        rpy="0 0 0" />
      <mass
        value="0.706316" />
      <inertia
        ixx="0.000403"
        ixy="0.000018"
        ixz="0.0"
        iyy="0.000535"
        iyz="-0.000001"
        izz="0.000446" />
    </inertial>
    <visual>
      <origin
        xyz="0 0 0"
        rpy="0 0 0" />
      <geometry>
        <!-- <mesh
          filename="../meshes/LF_hip.STL" /> -->
          <mesh
          filename="package://legged_damiao_description/meshes/dmgo/LF_hip.STL" />
      </geometry>
      <material
        name="">
        <color
          rgba="0.43921568627451 0.43921568627451 0.43921568627451 1" />
      </material>
    </visual>
    <!-- <collision>
      <origin rpy="0 1.5708 1.5708" xyz="0.04756 -0.010434 -0.000046"/>
      <geometry>
        <cylinder length="0.03" radius="0.03"/>
      </geometry>
    </collision> -->
    <collision>
      <origin
        xyz="0 0 0"
        rpy="0 0 0" />
      <geometry>
        <box size="0.0001 0.0001 0.0001" />
      </geometry>
    </collision>
  </link>
  <joint
    name="LF_HAA"
    type="revolute">
    <origin
      xyz="0.16175 0.059997 -0.061498"
      rpy="0 0 0" />
    <parent
      link="base" />
    <child
      link="LF_hip" />
    <axis
      xyz="1 0 0" />
    <dynamics damping="0" friction="0.0"/>
    <limit
      lower="-1.57"
      upper="1.57"
      effort="20.0"
      velocity="52.4" />
  </joint>



  <link
    name="LF_thigh">
    <inertial>
      <origin
        xyz="-0.023554 0.050542 0.001956"
        rpy="0 0 0" />
      <mass
        value="0.977146" />
      <inertia
        ixx="0.000887"
        ixy="0.000644"
        ixz="0.000176"
        iyy="0.003756"
        iyz="-0.000057"
        izz="0.003918" />
    </inertial>
    <visual>
      <origin
        xyz="0 0 0"
        rpy="0 0 0" />
      <geometry>
        <mesh
          filename="package://legged_damiao_description/meshes/dmgo/LF_thigh.STL" />
      </geometry>
      <material
        name="">
        <color
          rgba="0.898039215686275 0.917647058823529 0.929411764705882 1" />
      </material>
    </visual>
    <!-- <collision>
      <origin
        xyz="0 0 0"
        rpy="0 0 0" />
      <geometry>
        <mesh
          filename="package://legged_damiao_description/meshes/FL_thigh.STL" />
      </geometry>
    </collision> -->
    <collision> 
      <origin rpy="0 0.1 0" xyz="-0.07 0.08 0.016"/>
      <geometry>
        <box size="0.15 0.03 0.035"/>
      </geometry>
    </collision>
  </link>
  <joint
    name="LF_HFE"
    type="revolute">
    <origin
      xyz="0.049998 0.019503 0"
      rpy="0 0 0" />
    <parent
      link="LF_hip" />
    <child
      link="LF_thigh" />
    <axis
      xyz="0 1 0" />
    <dynamics damping="0" friction="0.0"/>
    <limit
      lower="-1.57"
      upper="2.4"
      effort="55.0"
      velocity="28.6" />
  </joint>











  <link
    name="LF_calf">
    <inertial>
      <origin
        xyz="-0.010235 0.000248 -0.054204"
        rpy="0 0 0" />
      <mass
        value="0.240236" />
      <inertia
        ixx="0.000969"
        ixy="-0.000004"
        ixz="-0.001737"
        iyy="0.005316"
        iyz="-0.000004"
        izz="0.004359" />
    </inertial>
    <visual>
      <origin
        xyz="0 0 0"
        rpy="0 0 0" />
      <geometry>
        <mesh
          filename="package://legged_damiao_description/meshes/dmgo/LF_calf.STL" />
      </geometry>
      <material
        name="">
        <color
          rgba="0.898039215686275 0.917647058823529 0.929411764705882 1" />
      </material>
    </visual>
    <collision> 
      <origin rpy="0 -0.76 0" xyz="-0.08 0.0 -0.08"/>
      <geometry>
        <box size="0.18 0.015 0.018"/>
      </geometry>
    </collision>
    <!-- <collision>
      <origin
        xyz="0 0 0"
        rpy="0 0 0" />
      <geometry>
        <mesh
          filename="package://legged_damiao_description/meshes/FL_calf.STL" />
      </geometry>
    </collision> -->
  </link>
  <joint
    name="LF_KFE"
    type="revolute">
    <origin
      xyz="-0.2 0.07825 0"
      rpy="0 0 0" />
    <parent
      link="LF_thigh" />
    <child
      link="LF_calf" />
    <axis
      xyz="0 1 0" />
    <limit
      lower="-2.25"
      upper="0.5"
      effort="55"
      velocity="28.6" />
  </joint>


  <link
    name="LF_FOOT">
    <inertial>
      <origin
        xyz="-0.000269 -0.0002 -0.000005"
        rpy="0 0 0" />
      <mass
        value="0.030285" />
      <inertia
        ixx="0.000008"
        ixy="0.0"
        ixz="0.0"
        iyy="0.000005"
        iyz="0.0"
        izz="0.000008" />
    </inertial>
    <visual>
      <origin
        xyz="0 0 0"
        rpy="0 0 0" />
      <geometry>
        <mesh
          filename="package://legged_damiao_description/meshes/dmgo/LF_FOOT.STL" />
      </geometry>
      <material
        name="">
        <color
          rgba="0.298039215686275 0.298039215686275 0.298039215686275 1" />
      </material>
    </visual>
    <collision>
      <origin rpy="0 0 0" xyz="0 0 0"/>
      <geometry>
        <sphere radius="0.02"/>
      </geometry>
    </collision>
    <!-- <collision>
      <origin
        xyz="0 0 0"
        rpy="0 0 0" />
      <geometry>
        <mesh
          filename="package://legged_damiao_description/meshes/FL_foot.STL" />
      </geometry>
    </collision> -->
  </link>
  <joint
    name="LF_foot_fixed"
    type="fixed"  dont_collapse="true">
    <origin
      xyz="-0.17362 0 -0.14312"
      rpy="0 0 0" />
    <parent
      link="LF_calf" />
    <child
      link="LF_FOOT" />
    <axis
      xyz="0 0 0" />
  </joint>


  <gazebo reference="LF_foot_fixed">
    <disableFixedJointLumping>true</disableFixedJointLumping>
  </gazebo>
  <gazebo reference="LF_hip">
    <mu1>0.2</mu1>
    <mu2>0.2</mu2>
    <material>Gazebo/DarkGrey</material>
  </gazebo>
  <gazebo reference="LF_thigh">
    <mu1>0.2</mu1>
    <mu2>0.2</mu2>
    <self_collide>0</self_collide>
    <material>Gazebo/DarkGrey</material>
    <kp value="1000000.0"/>
    <kd value="100.0"/>
  </gazebo>
  <gazebo reference="LF_calf">
    <mu1>0.6</mu1>
    <mu2>0.6</mu2>
    <self_collide>1</self_collide>
  </gazebo>
  <gazebo reference="LF_FOOT">
    <mu1>0.6</mu1>
    <mu2>0.6</mu2>
    <self_collide>1</self_collide>
    <material>Gazebo/DarkGrey</material>
    <kp value="1000000.0"/>
    <kd value="100.0"/>
  </gazebo>
  <transmission name="LF_HAA_tran">
    <type>transmission_interface/SimpleTransmission</type>
    <joint name="LF_HAA">
      <hardwareInterface>hardware_interface/EffortJointInterface</hardwareInterface>
    </joint>
    <actuator name="LF_HAA_motor">
      <hardwareInterface>hardware_interface/EffortJointInterface</hardwareInterface>
      <mechanicalReduction>1</mechanicalReduction>
    </actuator>
  </transmission>
  <transmission name="LF_HFE_tran">
    <type>transmission_interface/SimpleTransmission</type>
    <joint name="LF_HFE">
      <hardwareInterface>hardware_interface/EffortJointInterface</hardwareInterface>
    </joint>
    <actuator name="LF_HFE_motor">
      <hardwareInterface>hardware_interface/EffortJointInterface</hardwareInterface>
      <mechanicalReduction>1</mechanicalReduction>
    </actuator>
  </transmission>
  <transmission name="LF_KFE_tran">
    <type>transmission_interface/SimpleTransmission</type>
    <joint name="LF_KFE">
      <hardwareInterface>hardware_interface/EffortJointInterface</hardwareInterface>
    </joint>
    <actuator name="LF_KFE_motor">
      <hardwareInterface>hardware_interface/EffortJointInterface</hardwareInterface>
      <mechanicalReduction>1</mechanicalReduction>
    </actuator>
  </transmission>


  <link
    name="LH_hip">
    <inertial>
      <origin
        xyz="-0.047555 -0.010434 -0.000042"
        rpy="0 0 0" />
      <mass
        value="0.706316" />
      <inertia
        ixx="0.000403"
        ixy="-0.000018"
        ixz="0.0"
        iyy="0.000535"
        iyz="-0.000001"
        izz="0.000446" />
    </inertial>
    <visual>
      <origin
        xyz="0 0 0"
        rpy="0 0 0" />
      <geometry>
        <!-- <mesh
          filename="../meshes/LH_hip.STL" /> -->
        <mesh
          filename="package://legged_damiao_description/meshes/dmgo/LH_hip.STL" />
      </geometry>
      <material
        name="">
        <color
          rgba="1 1 1 1" />
      </material>
    </visual>
    <!-- <collision>
      <origin rpy="0 1.5708 1.5708" xyz="-0.04756 -0.010434 -0.000046"/>
      <geometry>
        <cylinder length="0.03" radius="0.03"/>
      </geometry>
    </collision> -->
    <collision>
      <origin
        xyz="0 0 0"
        rpy="0 0 0" />
      <geometry>
        <box size="0.0001 0.0001 0.0001" />
      </geometry>
    </collision>
  </link>
  <joint
    name="LH_HAA"
    type="revolute">
    <origin
      xyz="-0.16175 0.059997 -0.061502"
      rpy="0 0 0" />
    <parent
      link="base" />
    <child
      link="LH_hip" />
    <axis
      xyz="1 0 0" />
    <dynamics damping="0" friction="0.0"/>
    <limit
      lower="-1.57"
      upper="1.57"
      effort="20.0"
      velocity="52.4" />
  </joint>

  <link
    name="LH_thigh">
    <inertial>
      <origin
        xyz="-0.023554 0.050542 0.001956"
        rpy="0 0 0" />
      <mass
        value="0.977146" />
      <inertia
        ixx="0.000887"
        ixy="0.000644"
        ixz="0.000176"
        iyy="0.003756"
        iyz="-0.000057"
        izz="0.003918" />
    </inertial>
    <visual>
      <origin
        xyz="0 0 0"
        rpy="0 0 0" />
      <geometry>
        <mesh
          filename="package://legged_damiao_description/meshes/dmgo/LH_thigh.STL" />
      </geometry>
      <material
        name="">
        <color
          rgba="0.898039215686275 0.917647058823529 0.929411764705882 1" />
      </material>
    </visual>
    <collision> 
      <origin rpy="0 0.1 0" xyz="-0.07 0.08 0.016"/>
      <geometry>
        <box size="0.15 0.03 0.035"/>
      </geometry>
    </collision>
    <!-- <collision>
      <origin
        xyz="0 0 0"
        rpy="0 0 0" />
      <geometry>
        <mesh
          filename="package://legged_damiao_description/meshes/RL_thigh.STL" />
      </geometry>
    </collision> -->
  </link>
  <joint
    name="LH_HFE"
    type="revolute">
    <origin
      xyz="-0.050002 0.019503 0"
      rpy="0 0 0" />
    <parent
      link="LH_hip" />
    <child
      link="LH_thigh" />
    <axis
      xyz="0 1 0" />
    <dynamics damping="0" friction="0.0"/>
    <limit
      lower="-1.57"
      upper="2.4"
      effort="55.0"
      velocity="28.6" />
  </joint>





  <link
    name="LH_calf">
    <inertial>
      <origin
        xyz="-0.010235 0.000248 -0.054204"
        rpy="0 0 0" />
      <mass
        value="0.240236" />
      <inertia
        ixx="0.000969"
        ixy="-0.000004"
        ixz="-0.001737"
        iyy="0.005316"
        iyz="-0.000004"
        izz="0.004359" />
    </inertial>
    <visual>
      <origin
        xyz="0 0 0"
        rpy="0 0 0" />
      <geometry>
        <mesh
          filename="package://legged_damiao_description/meshes/dmgo/LH_calf.STL" />
      </geometry>
      <material
        name="">
        <color
          rgba="0.898039215686275 0.917647058823529 0.929411764705882 1" />
      </material>
    </visual>
    <collision> 
      <origin rpy="0 -0.76 0" xyz="-0.08 0.0 -0.08"/>
      <geometry>
        <box size="0.18 0.015 0.018"/>
      </geometry>
    </collision>
    <!-- <collision>
      <origin
        xyz="0 0 0"
        rpy="0 0 0" />
      <geometry>
        <mesh
          filename="package://legged_damiao_description/meshes/RL_calf.STL" />
      </geometry>
    </collision> -->
  </link>
  <joint
    name="LH_KFE"
    type="revolute">
    <origin
      xyz="-0.2 0.07825 0"
      rpy="0 0 0" />
    <parent
      link="LH_thigh" />
    <child
      link="LH_calf" />
    <axis
      xyz="0 1 0" />
    <limit
      lower="-2.25"
      upper="0.5"
      effort="55"
      velocity="28.6" />
  </joint>
  <link
    name="LH_FOOT">
    <inertial>
      <origin
        xyz="-0.000269 -0.0002 -0.000005"
        rpy="0 0 0" />
      <mass
        value="0.030285" />
      <inertia
        ixx="0.000008"
        ixy="0.0"
        ixz="0.0"
        iyy="0.000005"
        iyz="0.0"
        izz="0.000008" />
    </inertial>
    <visual>
      <origin
        xyz="0 0 0"
        rpy="0 0 0" />
      <geometry>
        <mesh
          filename="package://legged_damiao_description/meshes/dmgo/LH_FOOT.STL" />
      </geometry>
      <material
        name="">
        <color
          rgba="0.298039215686275 0.298039215686275 0.298039215686275 1" />
      </material>
    </visual>
     <collision>
      <origin rpy="0 0 0" xyz="0 0 0"/>
      <geometry>
        <sphere radius="0.02"/>
      </geometry>
    </collision>
    <!-- <collision>
      <origin
        xyz="0 0 0"
        rpy="0 0 0" />
      <geometry>
        <mesh
          filename="package://legged_damiao_description/meshes/RL_foot.STL" />
      </geometry>
    </collision> -->
  </link>
  <joint
    name="LH_foot_fixed"
    type="fixed"  dont_collapse="true">
    <origin
      xyz="-0.17362 0 -0.14312"
      rpy="0 0 0" />
    <parent
      link="LH_calf" />
    <child
      link="LH_FOOT" />
    <axis
      xyz="0 0 0" />
  </joint>


   <gazebo reference="LH_foot_fixed">
    <disableFixedJointLumping>true</disableFixedJointLumping>
  </gazebo>
  <gazebo reference="LH_hip">
    <mu1>0.2</mu1>
    <mu2>0.2</mu2>
    <material>Gazebo/DarkGrey</material>
  </gazebo>
  <gazebo reference="LH_thigh">
    <mu1>0.2</mu1>
    <mu2>0.2</mu2>
    <self_collide>0</self_collide>
    <material>Gazebo/DarkGrey</material>
    <kp value="1000000.0"/>
    <kd value="100.0"/>
  </gazebo>
  <gazebo reference="LH_calf">
    <mu1>0.6</mu1>
    <mu2>0.6</mu2>
    <self_collide>1</self_collide>
  </gazebo>
  <gazebo reference="LH_FOOT">
    <mu1>0.6</mu1>
    <mu2>0.6</mu2>
    <self_collide>1</self_collide>
    <material>Gazebo/DarkGrey</material>
    <kp value="1000000.0"/>
    <kd value="100.0"/>
  </gazebo>
  <transmission name="LH_HAA_tran">
    <type>transmission_interface/SimpleTransmission</type>
    <joint name="LH_HAA">
      <hardwareInterface>hardware_interface/EffortJointInterface</hardwareInterface>
    </joint>
    <actuator name="LH_HAA_motor">
      <hardwareInterface>hardware_interface/EffortJointInterface</hardwareInterface>
      <mechanicalReduction>1</mechanicalReduction>
    </actuator>
  </transmission>
  <transmission name="LH_HFE_tran">
    <type>transmission_interface/SimpleTransmission</type>
    <joint name="LH_HFE">
      <hardwareInterface>hardware_interface/EffortJointInterface</hardwareInterface>
    </joint>
    <actuator name="LH_HFE_motor">
      <hardwareInterface>hardware_interface/EffortJointInterface</hardwareInterface>
      <mechanicalReduction>1</mechanicalReduction>
    </actuator>
  </transmission>
  <transmission name="LH_KFE_tran">
    <type>transmission_interface/SimpleTransmission</type>
    <joint name="LH_KFE">
      <hardwareInterface>hardware_interface/EffortJointInterface</hardwareInterface>
    </joint>
    <actuator name="LH_KFE_motor">
      <hardwareInterface>hardware_interface/EffortJointInterface</hardwareInterface>
      <mechanicalReduction>1</mechanicalReduction>
    </actuator>
  </transmission>




   <link
    name="RF_hip">
    <inertial>
      <origin
        xyz="0.047555 0.010661 -0.000046"
        rpy="0 0 0" />
      <mass
        value="0.706316" />
      <inertia
        ixx="0.000403"
        ixy="-0.000018"
        ixz="0.0"
        iyy="0.000535"
        iyz="0.000001"
        izz="0.000447" />
    </inertial>
    <visual>
      <origin
        xyz="0 0 0"
        rpy="0 0 0" />
      <geometry>
        <!-- <mesh
          filename="../meshes/RF_hip.STL" /> -->
        <mesh
          filename="package://legged_damiao_description/meshes/dmgo/RF_hip.STL" />
      </geometry>
      <material
        name="">
        <color
          rgba="0.43921568627451 0.43921568627451 0.43921568627451 1" />
      </material>
    </visual>
    <!-- <collision>
      <origin rpy="0 1.5708 1.5708" xyz="0.04756 0.010434 -0.000046"/>
      <geometry>
        <cylinder length="0.03" radius="0.03"/>
      </geometry>
    </collision> -->
    <collision>
      <origin
        xyz="0 0 0"
        rpy="0 0 0" />
      <geometry>
        <box size="0.0001 0.0001 0.0001" />
      </geometry>
    </collision>
  </link>
  <joint
    name="RF_HAA"
    type="revolute">
    <origin
      xyz="0.16175 -0.059983 -0.061498"
      rpy="0 0 0" />
    <parent
      link="base" />
    <child
      link="RF_hip" />
    <axis
      xyz="1 0 0" />
    <dynamics damping="0" friction="0.0"/>
    <limit
      lower="-1.57"
      upper="1.57"
      effort="20.0"
      velocity="52.4" />
  </joint>



  <link
    name="RF_thigh">
    <inertial>
      <origin
        xyz="-0.023592 -0.050542 0.001598"
        rpy="0 0 0" />
      <mass
        value="0.977146" />
      <inertia
        ixx="0.000882"
        ixy="-0.000645"
        ixz="0.000129"
        iyy="0.003756"
        iyz="0.000047"
        izz="0.003923" />
    </inertial>
    <visual>
      <origin
        xyz="0 0 0"
        rpy="0 0 0" />
      <geometry>
        <mesh
          filename="package://legged_damiao_description/meshes/dmgo/RF_thigh.STL" />
      </geometry>
      <material
        name="">
        <color
          rgba="0.898039215686275 0.917647058823529 0.929411764705882 1" />
      </material>
    </visual>
    <collision> 
      <origin rpy="0 0.1 0" xyz="-0.07 -0.08 0.016"/>
      <geometry>
        <box size="0.15 0.03 0.035"/>
      </geometry>
    </collision>
    <!-- <collision>
      <origin
        xyz="0 0 0"
        rpy="0 0 0" />
      <geometry>
        <mesh
          filename="package://legged_damiao_description/meshes/FR_thigh.STL" />
      </geometry>
    </collision> -->
  </link>
  <joint
    name="RF_HFE"
    type="revolute">
    <origin
      xyz="0.050002 -0.019247 0"
      rpy="0 0 0" />
    <parent
      link="RF_hip" />
    <child
      link="RF_thigh" />
    <axis
      xyz="0 1 0" />
    <dynamics damping="0" friction="0.0"/>
    <limit
      lower="-1.57"
      upper="2.4"
      effort="55.0"
      velocity="28.6" />
  </joint>






  <link
    name="RF_calf">
    <inertial>
      <origin
        xyz="-0.010245 -0.000248 -0.053503"
        rpy="0 0 0" />
      <mass
        value="0.240236" />
      <inertia
        ixx="0.000989"
        ixy="0.000004"
        ixz="-0.001772"
        iyy="0.005335"
        iyz="0.000004"
        izz="0.004358" />
    </inertial>
    <visual>
      <origin
        xyz="0 0 0"
        rpy="0 0 0" />
      <geometry>
        <mesh
          filename="package://legged_damiao_description/meshes/dmgo/RF_calf.STL" />
      </geometry>
      <material
        name="">
        <color
          rgba="0.898039215686275 0.917647058823529 0.929411764705882 1" />
      </material>
    </visual>
    <collision> 
      <origin rpy="0 -0.76 0" xyz="-0.08 0.0 -0.08"/>
      <geometry>
        <box size="0.18 0.015 0.018"/>
      </geometry>
    </collision>
    <!-- <collision>
      <origin
        xyz="0 0 0"
        rpy="0 0 0" />
      <geometry>
        <mesh
          filename="package://legged_damiao_description/meshes/FR_calf.STL" />
      </geometry>
    </collision> -->
  </link>
  <joint
    name="RF_KFE"
    type="revolute">
    <origin
      xyz="-0.19998 -0.07825 -0.003052"
      rpy="0 0 0" />
    <parent
      link="RF_thigh" />
    <child
      link="RF_calf" />
    <axis
      xyz="0 1 0" />
    <limit
      lower="-2.25"
      upper="0.5"
      effort="55.0"
      velocity="28.6" />
  </joint>
  <link
    name="RF_FOOT">
    <inertial>
      <origin
        xyz="-0.000269 0.0002 -0.000005"
        rpy="0 0 0" />
      <mass
        value="0.030285" />
      <inertia
        ixx="0.000008"
        ixy="0.0"
        ixz="0.0"
        iyy="0.000005"
        iyz="0.0"
        izz="0.000008" />
    </inertial>
    <visual>
      <origin
        xyz="0 0 0"
        rpy="0 0 0" />
      <geometry>
        <mesh
          filename="package://legged_damiao_description/meshes/dmgo/RF_FOOT.STL" />
      </geometry>
      <material
        name="">
        <color
          rgba="1 1 1 1" />
      </material>
    </visual>
     <collision>
      <origin rpy="0 0 0" xyz="0 0 0"/>
      <geometry>
        <sphere radius="0.02"/>
      </geometry>
    </collision>
    <!-- <collision>
      <origin
        xyz="0 0 0"
        rpy="0 0 0" />
      <geometry>
        <mesh
          filename="package://legged_damiao_description/meshes/FR_foot.STL" />
      </geometry>
    </collision> -->
  </link>
  <joint
    name="RF_foot_fixed"
    type="fixed" dont_collapse="true">
    <origin
      xyz="-0.17362 0 -0.14312"
      rpy="0 0 0" />
    <parent
      link="RF_calf" />
    <child
      link="RF_FOOT" />
    <axis
      xyz="0 0 0" />
  </joint>

  <gazebo reference="RF_foot_fixed">
    <disableFixedJointLumping>true</disableFixedJointLumping>
  </gazebo>
  <gazebo reference="RF_hip">
    <mu1>0.2</mu1>
    <mu2>0.2</mu2>
    <material>Gazebo/DarkGrey</material>
  </gazebo>
  <gazebo reference="RF_thigh">
    <mu1>0.2</mu1>
    <mu2>0.2</mu2>
    <self_collide>0</self_collide>
    <material>Gazebo/DarkGrey</material>
    <kp value="1000000.0"/>
    <kd value="100.0"/>
  </gazebo>
  <gazebo reference="RF_calf">
    <mu1>0.6</mu1>
    <mu2>0.6</mu2>
    <self_collide>1</self_collide>
  </gazebo>
  <gazebo reference="RF_FOOT">
    <mu1>0.6</mu1>
    <mu2>0.6</mu2>
    <self_collide>1</self_collide>
    <material>Gazebo/DarkGrey</material>
    <kp value="1000000.0"/>
    <kd value="100.0"/>
  </gazebo>
  <transmission name="RF_HAA_tran">
    <type>transmission_interface/SimpleTransmission</type>
    <joint name="RF_HAA">
      <hardwareInterface>hardware_interface/EffortJointInterface</hardwareInterface>
    </joint>
    <actuator name="RF_HAA_motor">
      <hardwareInterface>hardware_interface/EffortJointInterface</hardwareInterface>
      <mechanicalReduction>1</mechanicalReduction>
    </actuator>
  </transmission>
  <transmission name="RF_HFE_tran">
    <type>transmission_interface/SimpleTransmission</type>
    <joint name="RF_HFE">
      <hardwareInterface>hardware_interface/EffortJointInterface</hardwareInterface>
    </joint>
    <actuator name="RF_HFE_motor">
      <hardwareInterface>hardware_interface/EffortJointInterface</hardwareInterface>
      <mechanicalReduction>1</mechanicalReduction>
    </actuator>
  </transmission>
  <transmission name="RF_KFE_tran">
    <type>transmission_interface/SimpleTransmission</type>
    <joint name="RF_KFE">
      <hardwareInterface>hardware_interface/EffortJointInterface</hardwareInterface>
    </joint>
    <actuator name="RF_KFE_motor">
      <hardwareInterface>hardware_interface/EffortJointInterface</hardwareInterface>
      <mechanicalReduction>1</mechanicalReduction>
    </actuator>
  </transmission>

  



  <link
    name="RH_hip">
    <inertial>
      <origin
        xyz="-0.047555 0.010661 0.000046"
        rpy="0 0 0" />
      <mass
        value="0.706316" />
      <inertia
        ixx="0.000403"
        ixy="0.000018"
        ixz="0.0"
        iyy="0.000535"
        iyz="-0.000001"
        izz="0.000447" />
    </inertial>
    <visual>
      <origin
        xyz="0 0 0"
        rpy="0 0 0" />
      <geometry>
        <!-- <mesh
          filename="../meshes/RH_hip.STL" /> -->
        <mesh
          filename="package://legged_damiao_description/meshes/dmgo/RH_hip.STL" />
      </geometry>
      <material
        name="">
        <color
          rgba="0.43921568627451 0.43921568627451 0.43921568627451 1" />
      </material>
    </visual>
    <!-- <collision>
      <origin rpy="0 1.5708 1.5708" xyz="-0.04756 0.010434 -0.000046"/>
      <geometry>
        <cylinder length="0.03" radius="0.03"/>
      </geometry>
    </collision> -->
    <collision>
      <origin
        xyz="0 0 0"
        rpy="0 0 0" />
      <geometry>
        <box size="0.0001 0.0001 0.0001" />
      </geometry>
    </collision>
  </link>
  <joint
    name="RH_HAA"
    type="revolute">
    <origin
      xyz="-0.16175 -0.060003 -0.061502"
      rpy="0 0 0" />
    <parent
      link="base" />
    <child
      link="RH_hip" />
    <axis
      xyz="1 0 0" />
    <dynamics damping="0" friction="0.0"/>
    <limit
      lower="-1.57"
      upper="1.57"
      effort="20.0"
      velocity="52.4" />
  </joint>

  <link
    name="RH_thigh">
    <inertial>
      <origin
        xyz="-0.023592 -0.050542 0.001598"
        rpy="0 0 0" />
      <mass
        value="0.977146" />
      <inertia
        ixx="0.000882"
        ixy="-0.000645"
        ixz="0.000129"
        iyy="0.003756"
        iyz="0.000047"
        izz="0.003923" />
    </inertial>
    <visual>
      <origin
        xyz="0 0 0"
        rpy="0 0 0" />
      <geometry>
        <mesh
          filename="package://legged_damiao_description/meshes/dmgo/RH_thigh.STL" />
      </geometry>
      <material
        name="">
        <color
          rgba="0.898039215686275 0.917647058823529 0.929411764705882 1" />
      </material>
    </visual>
    <collision> 
      <origin rpy="0 0.1 0" xyz="-0.07 -0.08 0.016"/>
      <geometry>
        <box size="0.15 0.03 0.035"/>
      </geometry>
    </collision>
    <!-- <collision>
      <origin
        xyz="0 0 0"
        rpy="0 0 0" />
      <geometry>
        <mesh
          filename="package://legged_damiao_description/meshes/RR_thigh.STL" />
      </geometry>
    </collision> -->
  </link>
  <joint
    name="RH_HFE"
    type="revolute">
    <origin
      xyz="-0.050002 -0.019247 0"
      rpy="0 0 0" />
    <parent
      link="RH_hip" />
    <child
      link="RH_thigh" />
    <axis
      xyz="0 1 0" />
    <dynamics damping="0" friction="0.0"/>
    <limit
      lower="-1.57"
      upper="2.4"
      effort="55.0"
      velocity="28.6" />
  </joint>






  <link
    name="RH_calf">
    <inertial>
      <origin
        xyz="-0.010245 -0.000248 -0.053503"
        rpy="0 0 0" />
      <mass
        value="0.240236" />
      <inertia
        ixx="0.000989"
        ixy="0.000004"
        ixz="-0.001772"
        iyy="0.005335"
        iyz="0.000004"
        izz="0.004358" />
    </inertial>
    <visual>
      <origin
        xyz="0 0 0"
        rpy="0 0 0" />
      <geometry>
        <mesh
          filename="package://legged_damiao_description/meshes/dmgo/RH_calf.STL" />
      </geometry>
      <material
        name="">
        <color
          rgba="0.898039215686275 0.917647058823529 0.929411764705882 1" />
      </material>
    </visual>
    <collision> 
      <origin rpy="0 -0.76 0" xyz="-0.08 0.0 -0.08"/>
      <geometry>
        <box size="0.18 0.015 0.018"/>
      </geometry>
    </collision>
    <!-- <collision>
      <origin
        xyz="0 0 0"
        rpy="0 0 0" />
      <geometry>
        <mesh
          filename="package://legged_damiao_description/meshes/RR_calf.STL" />
      </geometry>
    </collision> -->
  </link>
  <joint
    name="RH_KFE"
    type="revolute">
    <origin
      xyz="-0.19998 -0.07825 -0.003052"
      rpy="0 0 0" />
    <parent
      link="RH_thigh" />
    <child
      link="RH_calf" />
    <axis
      xyz="0 1 0" />
    <limit
      lower="-2.25"
      upper="0.5"
      effort="55.0"
      velocity="28.6" />
  </joint>


  <link
    name="RH_FOOT">
    <inertial>
      <origin
        xyz="-0.000269 0.0002 -0.000005"
        rpy="0 0 0" />
      <mass
        value="0.030285" />
      <inertia
        ixx="0.000008"
        ixy="0.0"
        ixz="0.0"
        iyy="0.000005"
        iyz="0.0"
        izz="0.000008" />
    </inertial>
    <visual>
      <origin
        xyz="0 0 0"
        rpy="0 0 0" />
      <geometry>
        <mesh
          filename="package://legged_damiao_description/meshes/dmgo/RH_FOOT.STL" />
      </geometry>
      <material
        name="">
        <color
          rgba="1 1 1 1" />
      </material>
    </visual>
     <collision>
      <origin rpy="0 0 0" xyz="0 0 0"/>
      <geometry>
        <sphere radius="0.02"/>
      </geometry>
    </collision>
    <!-- <collision>
      <origin
        xyz="0 0 0"
        rpy="0 0 0" />
      <geometry>
        <mesh
          filename="package://legged_damiao_description/meshes/RR_foot.STL" />
      </geometry>
    </collision> -->
  </link>
  <joint
    name="RH_foot_fixed"
    type="fixed" dont_collapse="true">
    <origin
      xyz="-0.173615531262253 0 -0.143117599562475"
      rpy="0 0 0" />
    <parent
      link="RH_calf" />
    <child
      link="RH_FOOT" />
    <axis
      xyz="0 0 0" />
  </joint>



  <gazebo reference="RH_foot_fixed">
    <disableFixedJointLumping>true</disableFixedJointLumping>
  </gazebo>
  <gazebo reference="RH_hip">
    <mu1>0.2</mu1>
    <mu2>0.2</mu2>
    <material>Gazebo/DarkGrey</material>
  </gazebo>
  <gazebo reference="RH_thigh">
    <mu1>0.2</mu1>
    <mu2>0.2</mu2>
    <self_collide>0</self_collide>
    <material>Gazebo/DarkGrey</material>
    <kp value="1000000.0"/>
    <kd value="100.0"/>
  </gazebo>
  <gazebo reference="RH_calf">
    <mu1>0.6</mu1>
    <mu2>0.6</mu2>
    <self_collide>1</self_collide>
  </gazebo>
  <gazebo reference="RH_FOOT">
    <mu1>0.6</mu1>
    <mu2>0.6</mu2>
    <self_collide>1</self_collide>
    <material>Gazebo/DarkGrey</material>
    <kp value="1000000.0"/>
    <kd value="100.0"/>
  </gazebo>
  <transmission name="RH_HAA_tran">
    <type>transmission_interface/SimpleTransmission</type>
    <joint name="RH_HAA">
      <hardwareInterface>hardware_interface/EffortJointInterface</hardwareInterface>
    </joint>
    <actuator name="RH_HAA_motor">
      <hardwareInterface>hardware_interface/EffortJointInterface</hardwareInterface>
      <mechanicalReduction>1</mechanicalReduction>
    </actuator>
  </transmission>
  <transmission name="RH_HFE_tran">
    <type>transmission_interface/SimpleTransmission</type>
    <joint name="RH_HFE">
      <hardwareInterface>hardware_interface/EffortJointInterface</hardwareInterface>
    </joint>
    <actuator name="RH_HFE_motor">
      <hardwareInterface>hardware_interface/EffortJointInterface</hardwareInterface>
      <mechanicalReduction>1</mechanicalReduction>
    </actuator>
  </transmission>
  <transmission name="RH_KFE_tran">
    <type>transmission_interface/SimpleTransmission</type>
    <joint name="RH_KFE">
      <hardwareInterface>hardware_interface/EffortJointInterface</hardwareInterface>
    </joint>
    <actuator name="RH_KFE_motor">
      <hardwareInterface>hardware_interface/EffortJointInterface</hardwareInterface>
      <mechanicalReduction>1</mechanicalReduction>
    </actuator>
  </transmission>



</robot>
