<?xml version="1.0"?>

<robot xmlns:xacro="http://www.ros.org/wiki/xacro">

    <xacro:include filename="$(find legged_unitree_description)/urdf/common/transmission.xacro"/>

    <xacro:macro name="leg" params="prefix mesh_path mirror mirror_dae front_hind front_hind_dae *origin">

        <joint name="${prefix}_HAA" type="revolute">
            <xacro:insert_block name="origin"/>
            <parent link="base"/>
            <child link="${prefix}_hip"/>
            <axis xyz="1 0 0"/>
            <dynamics damping="${damping}" friction="${friction}"/>
            <xacro:if value="${(mirror_dae == True)}">
                <limit effort="${hip_torque_max}" velocity="${hip_velocity_max}" lower="${hip_position_min}"
                       upper="${hip_position_max}"/>
            </xacro:if>
            <xacro:if value="${(mirror_dae == False)}">
                <limit effort="${hip_torque_max}" velocity="${hip_velocity_max}" lower="${-hip_position_max}"
                       upper="${-hip_position_min}"/>
            </xacro:if>
        </joint>

        <link name="${prefix}_hip">
            <visual>
                 <origin rpy="0 0 0" xyz="0 0 0"/>
                <geometry>
                    <mesh filename="${mesh_path}/${prefix}_hip.STL"
                          scale="1 1 1"/>
                </geometry>
                <material name="orange"/>
            </visual>
            <collision>
                <origin rpy="0 1.5708 1.5708" xyz="${hip_x_offset*front_hind} ${hip_y_offset*mirror} -0.000046"/>
                <geometry>
                    <cylinder length="${hip_length}" radius="${hip_radius}"/>
                </geometry>
            </collision>
            <inertial>
                <origin rpy="0 0 0" xyz="${hip_com_x*front_hind} ${hip_com_y*mirror} ${hip_com_z}"/>
                <mass value="${hip_mass}"/>
                <inertia
                        ixx="${hip_ixx}" ixy="${hip_ixy*mirror*front_hind}" ixz="${hip_ixz*front_hind}"
                        iyy="${hip_iyy}" iyz="${hip_iyz*mirror}"
                        izz="${hip_izz}"/>
            </inertial>
        </link>

        <joint name="${prefix}_HFE" type="revolute">
            <origin rpy="0 0 0" xyz="${thighHFE_offsetx*front_hind} ${thighHFE_offsety*mirror} 0"/>
            <parent link="${prefix}_hip"/>
            <child link="${prefix}_thigh"/>
            <axis xyz="0 1 0"/>
            <dynamics damping="${damping}" friction="${friction}"/>
            <limit effort="${thigh_torque_max}" velocity="${thigh_velocity_max}" lower="${thigh_position_min}"
                   upper="${thigh_position_max}"/>
        </joint>

        <link name="${prefix}_thigh">
            <visual>
                <origin rpy="0 0 0" xyz="0 0 0"/>
                <geometry>
                    <xacro:if value="${mirror_dae == True}">
                        <mesh filename="${mesh_path}/${prefix}_thigh.STL"
                              scale="1 1 1"/>
                    </xacro:if>
                    <xacro:if value="${mirror_dae == False}">
                        <mesh filename="${mesh_path}/${prefix}_thigh.STL"
                              scale="1 1 1"/>
                    </xacro:if>
                </geometry>
                <material name="orange"/>
            </visual>
            <collision>
                <origin rpy="0 -0.1 0" xyz="${thigh_x_offset} ${thigh_y_offset*mirror} ${thigh_z_offset}"/>
                <geometry>
                    <box size="${thigh_length} ${thigh_width} ${thigh_height}"/>
                </geometry>
            </collision>
            <collision>
                <origin rpy="0 1.5708 1.5708" xyz="-0.010529 ${thigh_shoulder_y_offset*mirror} -0.004028"/>
                <geometry>
                    <cylinder length="${thigh_shoulder_length}" radius="${thigh_shoulder_radius}"/>
                </geometry>
            </collision>
            <inertial>
                <origin rpy="0 0 0" xyz="${thigh_com_x} ${thigh_com_y*mirror} ${thigh_com_z}"/>
                <mass value="${thigh_mass}"/>
                <inertia
                        ixx="${thigh_ixx}" ixy="${thigh_ixy*mirror}" ixz="${thigh_ixz}"
                        iyy="${thigh_iyy}" iyz="${thigh_iyz*mirror}"
                        izz="${thigh_izz}"/>
            </inertial>
        </link>

        <joint name="${prefix}_KFE" type="revolute">
            <origin rpy="0 0 0" xyz="-0.2 ${calfKFE_offsety*mirror} 0"/>
            <parent link="${prefix}_thigh"/>
            <child link="${prefix}_calf"/>
            <axis xyz="0 1 0"/>
            <dynamics damping="${damping}" friction="${friction}"/>
            <limit effort="${calf_torque_max}" velocity="${calf_velocity_max}" lower="${calf_position_min}" upper="${calf_position_max}"/>
        </joint>

        <link name="${prefix}_calf">
            <visual>
                <origin rpy="0 0 0" xyz="0 0 0"/>
                <geometry>
                    <mesh filename="${mesh_path}/${prefix}_calf.STL"
                          scale="1 1 1"/>
                </geometry>
                <material name="orange"/>
            </visual>
            <collision>
                <origin rpy="0 -0.76 0" xyz="${calf_x_offset} 0 ${calf_z_offset}"/>
                <geometry>
                    <box size="${calf_length} ${calf_width} ${calf_height}"/>
                </geometry>
            </collision>
            <inertial>
                <origin rpy="0 0 0" xyz="${calf_com_x} ${calf_com_y} ${calf_com_z}"/>
                <mass value="${calf_mass}"/>
                <inertia
                        ixx="${calf_ixx}" ixy="${calf_ixy}" ixz="${calf_ixz}"
                        iyy="${calf_iyy}" iyz="${calf_iyz}"
                        izz="${calf_izz}"/>
            </inertial>
        </link>

        <joint name="${prefix}_foot_fixed" type="fixed" dont_collapse="true">
            <origin rpy="0 0 0" xyz="-0.17362 ${foot_fixed_y*mirror} -0.14312"/>
            <parent link="${prefix}_calf"/>
            <child link="${prefix}_FOOT"/>
        </joint>

        <link name="${prefix}_FOOT">
            <visual>
                <origin rpy="0 0 0" xyz="0 0 0"/>
                <geometry>
                    <mesh filename="${mesh_path}/${prefix}_FOOT.STL"
                          scale="1 1 1"/>
                </geometry>
                <material name="orange"/>
            </visual>
            <collision>
                <origin rpy="0 0 0" xyz="0 0 0"/>
                <geometry>
                    <sphere radius="${foot_radius}"/>
                </geometry>
            </collision>
            <inertial>
                <mass value="${foot_mass}"/>
                <inertia
                        ixx="${foot_ixx}" ixy="${foot_ixy}" ixz="${foot_ixz}"
                        iyy="${foot_iyy}" iyz="${foot_iyz}" izz="${foot_izz}"/>
            </inertial>
        </link>

        <gazebo reference="${prefix}_foot_fixed">
            <disableFixedJointLumping>true</disableFixedJointLumping>
        </gazebo>

        <gazebo reference="${prefix}_hip">
            <mu1>0.2</mu1>
            <mu2>0.2</mu2>
            <material>Gazebo/DarkGrey</material>
        </gazebo>
        <gazebo reference="${prefix}_thigh">
            <mu1>0.2</mu1>
            <mu2>0.2</mu2>
            <self_collide>0</self_collide>
            <material>Gazebo/DarkGrey</material>
            <kp value="1000000.0"/>
            <kd value="100.0"/>
        </gazebo>
        <gazebo reference="${prefix}_calf">
            <mu1>0.6</mu1>
            <mu2>0.6</mu2>
            <self_collide>1</self_collide>
        </gazebo>
        <gazebo reference="${prefix}_FOOT">
            <mu1>0.6</mu1>
            <mu2>0.6</mu2>
            <self_collide>1</self_collide>
            <material>Gazebo/DarkGrey</material>
            <kp value="1000000.0"/>
            <kd value="100.0"/>
        </gazebo>

        <xacro:leg_transmission name="${prefix}"/>
    </xacro:macro>
</robot>
